Workbook

Sheet Totals
A1: PlayerUnique | B1: Team | C1: total_expected_votes | E1: Round No | F1: Leader
A2: Daicos, Nick | B2: COLL | C2: =SUMIF(Predictions!$A$2:$A$10000,A2,Predictions!$F$2:$F$10000) -> 7.6322475 | E2: 0 | F2: Christian Petracca
A3: Bontempelli, Marcus | B3: WB | C3: =SUMIF(Predictions!$A$2:$A$10000,A3,Predictions!$F$2:$F$10000) -> 7.3998028 | E3: 1 | F3: Christian Petracca
A4: Smith, Bailey | B4: GEEL | C4: =SUMIF(Predictions!$A$2:$A$10000,A4,Predictions!$F$2:$F$10000) -> 7.0097488 | E4: 2 | F4: Marcus Bontempelli
A5: Heeney, Isaac | B5: SYD | C5: =SUMIF(Predictions!$A$2:$A$10000,A5,Predictions!$F$2:$F$10000) -> 5.8155266 | E5: 3 | F5: Nick Daicos
A6: Butters, Zak | B6: PORT | C6: =SUMIF(Predictions!$A$2:$A$10000,A6,Predictions!$F$2:$F$10000) -> 5.7947414 | E6: 4 | F6: Marcus Bontempelli
A7: Callaghan, Finn | B7: GWS | C7: =SUMIF(Predictions!$A$2:$A$10000,A7,Predictions!$F$2:$F$10000) -> 5.6062267 | E7: 5 | F7: Nick Daicos
A8: Kennedy, Matthew | B8: WB | C8: =SUMIF(Predictions!$A$2:$A$10000,A8,Predictions!$F$2:$F$10000) -> 5.599588 | E8: 6
A9: Gawn, Max | B9: MELB | C9: =SUMIF(Predictions!$A$2:$A$10000,A9,Predictions!$F$2:$F$10000) -> 5.4343607 | E9: 7
A10: Pickett, Kysaiah | B10: MELB | C10: =SUMIF(Predictions!$A$2:$A$10000,A10,Predictions!$F$2:$F$10000) -> 5.3858676 | E10: 8
A11: Serong, Caleb | B11: FREM | C11: =SUMIF(Predictions!$A$2:$A$10000,A11,Predictions!$F$2:$F$10000) -> 5.2699822 | E11: 9
A12: Neale, Lachie | B12: BRIS | C12: =SUMIF(Predictions!$A$2:$A$10000,A12,Predictions!$F$2:$F$10000) -> 5.201816 | E12: 10
A13: Holmes, Max | B13: GEEL | C13: =SUMIF(Predictions!$A$2:$A$10000,A13,Predictions!$F$2:$F$10000) -> 4.8494298 | E13: 11
A14: Petracca, Christian | B14: GC | C14: =SUMIF(Predictions!$A$2:$A$10000,A14,Predictions!$F$2:$F$10000) -> 4.5532937 | E14: 12
A15: Ashcroft, Will | B15: BRIS | C15: =SUMIF(Predictions!$A$2:$A$10000,A15,Predictions!$F$2:$F$10000) -> 4.5229814 | E15: 13
A16: Warner, Chad | B16: SYD | C16: =SUMIF(Predictions!$A$2:$A$10000,A16,Predictions!$F$2:$F$10000) -> 4.4676699 | E16: 14
A17: Davies-Uniacke, Luke | B17: NM | C17: =SUMIF(Predictions!$A$2:$A$10000,A17,Predictions!$F$2:$F$10000) -> 4.3774494 | E17: 15
A18: Newcombe, Jai | B18: HAW | C18: =SUMIF(Predictions!$A$2:$A$10000,A18,Predictions!$F$2:$F$10000) -> 4.2316312 | E18: 16
A19: Richards, Ed | B19: WB | C19: =SUMIF(Predictions!$A$2:$A$10000,A19,Predictions!$F$2:$F$10000) -> 4.1314812 | E19: 17
... A26: Reid, Harley | B26: WCE | C26: =SUMIF(Predictions!$A$2:$A$10000,A26,Predictions!$F$2:$F$10000) -> 3.4596715 | E26: 24
A27: Treacy, Josh | B27: FREM | C27: =SUMIF(Predictions!$A$2:$A$10000,A27,Predictions!$F$2:$F$10000) -> 3.3035488
A28: Miller, Touk | B28: GC | C28: =SUMIF(Predictions!$A$2:$A$10000,A28,Predictions!$F$2:$F$10000) -> 3.2990648
A29: Grundy, Brodie | B29: SYD | C29: =SUMIF(Predictions!$A$2:$A$10000,A29,Predictions!$F$2:$F$10000) -> 3.2399572
A30: Roberts, Archie | B30: ESS | C30: =SUMIF(Predictions!$A$2:$A$10000,A30,Predictions!$F$2:$F$10000) -> 2.9636833
A31: McInerney, Justin | B31: SYD | C31: =SUMIF(Predictions!$A$2:$A$10000,A31,Predictions!$F$2:$F$10000) -> 2.8774112
A32: Bolton, Shai | B32: FREM | C32: =SUMIF(Predictions!$A$2:$A$10000,A32,Predictions!$F$2:$F$10000) -> 2.8032223
A33: King, Ben | B33: GC | C33: =SUMIF(Predictions!$A$2:$A$10000,A33,Predictions!$F$2:$F$10000) -> 2.7341037
A34: Merrett, Zach | B34: ESS | C34: =SUMIF(Predictions!$A$2:$A$10000,A34,Predictions!$F$2:$F$10000) -> 2.5486945
A35: Liberatore, Tom | B35: WB | C35: =SUMIF(Predictions!$A$2:$A$10000,A35,Predictions!$F$2:$F$10000) -> 2.489485
A36: Cripps, Patrick | B36: CARL | C36: =SUMIF(Predictions!$A$2:$A$10000,A36,Predictions!$F$2:$F$10000) -> 2.4590943
A37: Daicos, Josh | B37: COLL | C37: =SUMIF(Predictions!$A$2:$A$10000,A37,Predictions!$F$2:$F$10000) -> 2.2422864
A38: Naughton, Aaron | B38: WB | C38: =SUMIF(Predictions!$A$2:$A$10000,A38,Predictions!$F$2:$F$10000) -> 2.1756973
... A529: Alger, Jasper | B529: RICH | C529: =SUMIF(Predictions!$A$2:$A$10000,A529,Predictions!$F$2:$F$10000) -> 6.2136416e-07

Sheet Predictions
A1: PlayerName | B1: class_0 | C1: class_1 | D1: class_2 | E1: class_3 | F1: expected_votes | G1: BrownlowVotes
A2: Amartey, Joel | B2: 0.9953515 | C2: 0.003786921 | D2: 0.000790467 | E2: 7.12e-05 | F2: 0.005581548 | G2: {=_xlfn.IFS(F2=MAX($F$2:$F$47),3,F2=LARGE($F$2:$F$47,2),2,F2=LARGE($F$2:$F$47,3),1,TRUE,0)} -> 0
A3: Bice, Riley | B3: 0.99047315 | C3: 0.005215582 | D3: 0.003645999 | E3: 0.000665209 | F3: 0.014503209 | G3: {=_xlfn.IFS(F3=MAX($F$2:$F$47),3,F3=LARGE($F$2:$F$47,2),2,F3=LARGE($F$2:$F$47,3),1,TRUE,0)} -> 0
A4: Blakey, Nick | B4: 0.9728314 | C4: 0.017849378 | D4: 0.005733345 | E4: 0.003585849 | F4: 0.040073614 | G4: {=_xlfn.IFS(F4=MAX($F$2:$F$47),3,F4=LARGE($F$2:$F$47,2),2,F4=LARGE($F$2:$F$47,3),1,TRUE,0)} -> 0
A5: Curnow, Charlie | B5: 0.9935277 | C5: 0.005624921 | D5: 0.000766863 | E5: 8.04e-05 | F5: 0.007399848 | G5: {=_xlfn.IFS(F5=MAX($F$2:$F$47),3,F5=LARGE($F$2:$F$47,2),2,F5=LARGE($F$2:$F$47,3),1,TRUE,0)} -> 0
A6: Grundy, Brodie | B6: 0.78598964 | C6: 0.08437949 | D6: 0.10419589 | E6: 0.02543502 | F6: 0.36907633 | G6: {=_xlfn.IFS(F6=MAX($F$2:$F$47),3,F6=LARGE($F$2:$F$47,2),2,F6=LARGE($F$2:$F$47,3),1,TRUE,0)} -> 0
A7: Gulden, Errol | B7: 0.9308427 | C7: 0.021934979 | D7: 0.030169887 | E7: 0.017052345 | F7: 0.13343179 | G7: {=_xlfn.IFS(F7=MAX($F$2:$F$47),3,F7=LARGE($F$2:$F$47,2),2,F7=LARGE($F$2:$F$47,3),1,TRUE,0)} -> 0
A8: Heeney, Isaac | B8: 0.4658464 | C8: 0.19325258 | D8: 0.21831878 | E8: 0.12258216 | F8: 0.99763662 | G8: {=_xlfn.IFS(F8=MAX($F$2:$F$47),3,F8=LARGE($F$2:$F$47,2),2,F8=LARGE($F$2:$F$47,3),1,TRUE,0)} -> 2
A9: Jordon, James | B9: 0.9990897 | C9: 0.000669719 | D9: 0.000238241 | E9: 2.35e-06 | F9: 0.001153261 | G9: {=_xlfn.IFS(F9=MAX($F$2:$F$47),3,F9=LARGE($F$2:$F$47,2),2,F9=LARGE($F$2:$F$47,3),1,TRUE,0)} -> 0
A10: Lloyd, Jake | B10: 0.9987288 | C10: 0.000608594 | D10: 0.000653217 | E10: 9.26e-06 | F10: 0.001942795 | G10: {=_xlfn.IFS(F10=MAX($F$2:$F$47),3,F10=LARGE($F$2:$F$47,2),2,F10=LARGE($F$2:$F$47,3),1,TRUE,0)} -> 0
A11: McCartin, Tom | B11: 0.99108404 | C11: 0.004680436 | D11: 0.003461521 | E11: 0.000773881 | F11: 0.01392512 | G11: {=_xlfn.IFS(F11=MAX($F$2:$F$47),3,F11=LARGE($F$2:$F$47,2),2,F11=LARGE($F$2:$F$47,3),1,TRUE,0)} -> 0
A12: McDonald, Logan | B12: 0.9996588 | C12: 0.000313097 | D12: 2.54e-05 | E12: 2.8e-06 | F12: 0.000372252 | G12: {=_xlfn.IFS(F12=MAX($F$2:$F$47),3,F12=LARGE($F$2:$F$47,2),2,F12=LARGE($F$2:$F$47,3),1,TRUE,0)} -> 0
A13: McInerney, Justin | B13: 0.25371358 | C13: 0.15141672 | D13: 0.20709908 | E13: 0.3877706 | F13: 1.7289267 | G13: {=_xlfn.IFS(F13=MAX($F$2:$F$47),3,F13=LARGE($F$2:$F$47,2),2,F13=LARGE($F$2:$F$47,3),1,TRUE,0)} -> 3
... A47: Young, Lewis | B47: 0.9980328 | C47: 0.001052615 | D47: 0.000865952 | E47: 4.87e-05 | F47: 0.002930652 | G47: {=_xlfn.IFS(F47=MAX($F$2:$F$47),3,F47=LARGE($F$2:$F$47,2),2,F47=LARGE($F$2:$F$47,3),1,TRUE,0)} -> 0
A48: Adams, Oscar | B48: 0.99925375 | C48: 0.000459425 | D48: 0.000281329 | E48: 5.48e-06 | F48: 0.001038517 | G48: {=_xlfn.IFS(F48=MAX($F$48:$F$93),3,F48=LARGE($F$48:$F$93,2),2,F48=LARGE($F$48:$F$93,3),1,TRUE,0)} -> 0
A49: Anderson, Noah | B49: 0.3136083 | C49: 0.2667842 | D49: 0.22233006 | E49: 0.19727755 | F49: 1.303277 | G49: {=_xlfn.IFS(F49=MAX($F$48:$F$93),3,F49=LARGE($F$48:$F$93,2),2,F49=LARGE($F$48:$F$93,3),1,TRUE,0)} -> 2
A50: Andrew, Mac | B50: 0.9219974 | C50: 0.045943733 | D50: 0.022953678 | E50: 0.009105192 | F50: 0.11916667 | G50: {=_xlfn.IFS(F50=MAX($F$48:$F$93),3,F50=LARGE($F$48:$F$93,2),2,F50=LARGE($F$48:$F$93,3),1,TRUE,0)} -> 0
A51: Clohesy, Sam | B51: 0.99846286 | C51: 0.000820192 | D51: 0.000699928 | E51: 1.7e-05 | F51: 0.002270975 | G51: {=_xlfn.IFS(F51=MAX($F$48:$F$93),3,F51=LARGE($F$48:$F$93,2),2,F51=LARGE($F$48:$F$93,3),1,TRUE,0)} -> 0
A52: Collins, Sam | B52: 0.97229916 | C52: 0.01576532 | D52: 0.007878657 | E52: 0.004056731 | F52: 0.043692827 | G52: {=_xlfn.IFS(F52=MAX($F$48:$F$93),3,F52=LARGE($F$48:$F$93,2),2,F52=LARGE($F$48:$F$93,3),1,TRUE,0)} -> 0
A53: Davies, Alex | B53: 0.9768198 | C53: 0.017726643 | D53: 0.004575338 | E53: 0.000878278 | F53: 0.029512152 | G53: {=_xlfn.IFS(F53=MAX($F$48:$F$93),3,F53=LARGE($F$48:$F$93,2),2,F53=LARGE($F$48:$F$93,3),1,TRUE,0)} -> 0
A54: Farrar, Jy | B54: 0.9999704 | C54: 2.8e-05 | D54: 1.59e-06 | E54: 4.33e-08 | F54: 3.12722e-05 | G54: {=_xlfn.IFS(F54=MAX($F$48:$F$93),3,F54=LARGE($F$48:$F$93,2),2,F54=LARGE($F$48:$F$93,3),1,TRUE,0)} -> 0
A55: Graham, Will | B55: 0.99966586 | C55: 0.000269472 | D55: 6.36e-05 | E55: 1.03e-06 | F55: 0.00039986 | G55: {=_xlfn.IFS(F55=MAX($F$48:$F$93),3,F55=LARGE($F$48:$F$93,2),2,F55=LARGE($F$48:$F$93,3),1,TRUE,0)} -> 0
A56: Humphrey, Bailey | B56: 0.7386751 | C56: 0.12890276 | D56: 0.10475964 | E56: 0.027662449 | F56: 0.42140939 | G56: {=_xlfn.IFS(F56=MAX($F$48:$F$93),3,F56=LARGE($F$48:$F$93,2),2,F56=LARGE($F$48:$F$93,3),1,TRUE,0)} -> 0
A57: Jeffrey, Joel | B57: 0.9846744 | C57: 0.010691373 | D57: 0.004182286 | E57: 0.000451854 | F57: 0.020411507 | G57: {=_xlfn.IFS(F57=MAX($F$48:$F$93),3,F57=LARGE($F$48:$F$93,2),2,F57=LARGE($F$48:$F$93,3),1,TRUE,0)} -> 0
A58: King, Ben | B58: 0.9450678 | C58: 0.04028355 | D58: 0.01341608 | E58: 0.001232431 | F58: 0.070813004 | G58: {=_xlfn.IFS(F58=MAX($F$48:$F$93),3,F58=LARGE($F$48:$F$93,2),2,F58=LARGE($F$48:$F$93,3),1,TRUE,0)} -> 0
A59: Lombard, Leo | B59: 0.9839322 | C59: 0.013663346 | D59: 0.002130357 | E59: 0.00027394 | F59: 0.018745881 | G59: {=_xlfn.IFS(F59=MAX($F$48:$F$93),3,F59=LARGE($F$48:$F$93,2),2,F59=LARGE($F$48:$F$93,3),1,TRUE,0)} -> 0
... A93: Worpel, James | B93: 0.99431705 | C93: 0.004677662 | D93: 0.000933565 | E93: 7.17e-05 | F93: 0.006759766 | G93: {=_xlfn.IFS(F93=MAX($F$48:$F$93),3,F93=LARGE($F$48:$F$93,2),2,F93=LARGE($F$48:$F$93,3),1,TRUE,0)} -> 0
A94: Angwin, Ryan | B94: 0.9992479 | C94: 0.000650764 | D94: 0.000100613 | E94: 7.6e-07 | F94: 0.00085427 | G94: {=_xlfn.IFS(F94=MAX($F$94:$F$139),3,F94=LARGE($F$94:$F$139,2),2,F94=LARGE($F$94:$F$139,3),1,TRUE,0)} -> 0
A95: Ash, Lachie | B95: 0.93500286 | C95: 0.047818217 | D95: 0.011962028 | E95: 0.005216939 | F95: 0.087393091 | G95: {=_xlfn.IFS(F95=MAX($F$94:$F$139),3,F95=LARGE($F$94:$F$139,2),2,F95=LARGE($F$94:$F$139,3),1,TRUE,0)} -> 0
A96: Briggs, Kieren | B96: 0.9874645 | C96: 0.007092735 | D96: 0.005085703 | E96: 0.000356988 | F96: 0.018335105 | G96: {=_xlfn.IFS(F96=MAX($F$94:$F$139),3,F96=LARGE($F$94:$F$139,2),2,F96=LARGE($F$94:$F$139,3),1,TRUE,0)} -> 0
A97: Brown, Callum | B97: 0.9997494 | C97: 0.000227598 | D97: 2.14e-05 | E97: 1.55e-06 | F97: 0.000275038 | G97: {=_xlfn.IFS(F97=MAX($F$94:$F$139),3,F97=LARGE($F$94:$F$139,2),2,F97=LARGE($F$94:$F$139,3),1,TRUE,0)} -> 0
A98: Buckley, Jack | B98: 0.99794394 | C98: 0.00111951 | D98: 0.000906935 | E98: 2.96e-05 | F98: 0.003022224 | G98: {=_xlfn.IFS(F98=MAX($F$94:$F$139),3,F98=LARGE($F$94:$F$139,2),2,F98=LARGE($F$94:$F$139,3),1,TRUE,0)} -> 0
A99: Callaghan, Finn | B99: 0.35896415 | C99: 0.27326125 | D99: 0.20282526 | E99: 0.16494934 | F99: 1.1737598 | G99: {=_xlfn.IFS(F99=MAX($F$94:$F$139),3,F99=LARGE($F$94:$F$139,2),2,F99=LARGE($F$94:$F$139,3),1,TRUE,0)} -> 1
A100: Coniglio, Stephen | B100: 0.8041849 | C100: 0.064248554 | D100: 0.066983305 | E100: 0.06458319 | F100: 0.39196473 | G100: {=_xlfn.IFS(F100=MAX($F$94:$F$139),3,F100=LARGE($F$94:$F$139,2),2,F100=LARGE($F$94:$F$139,3),1,TRUE,0)} -> 0
A101: Delana, Josaia | B101: 0.9999092 | C101: 7.86e-05 | D101: 1.15e-05 | E101: 4.23e-07 | F101: 0.000102924 | G101: {=_xlfn.IFS(F101=MAX($F$94:$F$139),3,F101=LARGE($F$94:$F$139,2),2,F101=LARGE($F$94:$F$139,3),1,TRUE,0)} -> 0
A102: Fonti, Joe | B102: 0.87104374 | C102: 0.06870745 | D102: 0.038386766 | E102: 0.021861989 | F102: 0.21106695 | G102: {=_xlfn.IFS(F102=MAX($F$94:$F$139),3,F102=LARGE($F$94:$F$139,2),2,F102=LARGE($F$94:$F$139,3),1,TRUE,0)} -> 0
A103: Gothard, Phoenix | B103: 0.99879 | C103: 0.001122604 | D103: 7.93e-05 | E103: 8.21e-06 | F103: 0.001305849 | G103: {=_xlfn.IFS(F103=MAX($F$94:$F$139),3,F103=LARGE($F$94:$F$139,2),2,F103=LARGE($F$94:$F$139,3),1,TRUE,0)} -> 0
A104: Greene, Toby | B104: 0.8778819 | C104: 0.052540638 | D104: 0.050338168 | E104: 0.019239178 | F104: 0.21093451 | G104: {=_xlfn.IFS(F104=MAX($F$94:$F$139),3,F104=LARGE($F$94:$F$139,2),2,F104=LARGE($F$94:$F$139,3),1,TRUE,0)} -> 0
A105: Gruzewski, Max | B105: 0.9989896 | C105: 0.000802786 | D105: 0.000197724 | E105: 9.87e-06 | F105: 0.001227851 | G105: {=_xlfn.IFS(F105=MAX($F$94:$F$139),3,F105=LARGE($F$94:$F$139,2),2,F105=LARGE($F$94:$F$139,3),1,TRUE,0)} -> 0
... A139: Weddle, Josh | B139: 0.99957544 | C139: 0.000226472 | D139: 0.000196731 | E139: 1.33e-06 | F139: 0.000623918 | G139: {=_xlfn.IFS(F139=MAX($F$94:$F$139),3,F139=LARGE($F$94:$F$139,2),2,F139=LARGE($F$94:$F$139,3),1,TRUE,0)} -> 0
...
